<?xml version="1.0" ?>
<!-- =================================================================================== -->
<!-- |    This document was autogenerated by xacro from inail2_dual_arm.urdf.xacro     | -->
<!-- |    EDITING THIS FILE BY HAND IS NOT RECOMMENDED                                 | -->
<!-- =================================================================================== -->
<robot name="inail2arm">
  <material name="grey">
    <color rgba="0.5 0.5 0.5 1"/>
  </material>
  <material name="dark_grey">
    <color rgba="0.3 0.3 0.3 1"/>
  </material>
  <material name="red">
    <color rgba="1.0 0.0 0.0 1"/>
  </material>
  <material name="green">
    <color rgba="0.0 1.0 0.0 1"/>
  </material>
  <material name="blue">
    <color rgba="0.13333333333333333 0.25882352941176473 0.7803921568627451 1.0"/>
  </material>
  <!-- /macro arms -->
  <!-- /macro ee -->
  <!-- Origin -->
  <link name="world"/>
  <joint name="world_joint" type="fixed">
    <parent link="world"/>
    <child link="base_link"/>
    <origin xyz="0 0 1"/>
  </joint>
  <!-- torso -->
  <link name="base_link">
    <inertial>
      <origin xyz="0 0 0"/>
      <mass value="2.7764953"/>
      <inertia ixx="0.010002127" ixy="4.1468013999999995e-05" ixz="-5.1253649e-05" iyy="0.010728527" iyz="-0.00012700723" izz="0.006215603699999999"/>
    </inertial>
    <visual>
      <origin rpy="0.0 0.0 0.0" xyz="0.0 0.0 0.0"/>
      <geometry>
        <mesh filename="package://inail2arm_urdf/meshes/inail_torso.stl" scale="0.001 0.001 0.001"/>
      </geometry>
      <material name="dark_grey"/>
    </visual>
    <collision>
      <origin rpy="0.0 0.0 0.0" xyz="0.0 0.0 0.0"/>
      <geometry>
        <mesh filename="package://inail2arm_urdf/meshes/simple/inail_torso.stl" scale="0.001 0.001 0.001"/>
      </geometry>
    </collision>
  </link>
  <link name="mount_frame_1">
    <inertial>
      <origin rpy="0.0 0.0 0.0" xyz="0.0 0.0 0.0"/>
      <mass value="0.00001"/>
      <inertia ixx="0.0" ixy="0.0" ixz="0.0" iyy="0.0" iyz="0.0" izz="0.0"/>
    </inertial>
  </link>
  <joint name="mount_joint_1" type="fixed">
    <parent link="base_link"/>
    <child link="mount_frame_1"/>
    <origin rpy="0.7853981633975 0 0" xyz="0.065 -0.153361940777 0.221661940777"/>
  </joint>
  <!-- LINKS -->
  <!-- shoulder yaw-->
  <link name="arm1_1">
    <inertial>
      <origin xyz="8.4798664e-05 -0.020782662 0.032183554999999996"/>
      <mass value="0.41054046"/>
      <inertia ixx="0.0012949444" ixy="-1.8773371e-06" ixz="1.2479427999999998e-06" iyy="0.0012303834999999998" iyz="0.00032390228999999997" izz="0.0008036788199999999"/>
    </inertial>
    <visual>
      <origin rpy="0.0 0.0 0.0" xyz="0.0 0.0 0.0"/>
      <geometry>
        <mesh filename="package://inail2arm_urdf/meshes/mesh_shoulder-yaw.stl" scale="0.001 0.001 0.001"/>
      </geometry>
      <material name="blue"/>
    </visual>
    <collision>
      <origin rpy="0.0 0.0 0.0" xyz="0.0 0.0 0.0"/>
      <geometry>
        <mesh filename="package://inail2arm_urdf/meshes/simple/mesh_shoulder-yaw.stl" scale="0.001 0.001 0.001"/>
      </geometry>
    </collision>
  </link>
  <!-- shoulder yaw-->
  <!-- shoulder pitch-->
  <link name="arm1_2">
    <inertial>
      <origin xyz="-3.636067e-05 0.16072685 -0.062849027"/>
      <mass value="3.2487988"/>
      <inertia ixx="0.090371217" ixy="9.791527499999999e-05" ixz="-5.558155099999999e-06" iyy="0.0065574254" iyz="-0.0029068254" izz="0.088276594"/>
    </inertial>
    <visual>
      <origin rpy="0.0 0.0 0.0" xyz="0.0 0.0 0.0"/>
      <geometry>
        <mesh filename="package://inail2arm_urdf/meshes/mesh_shoulder-pitch.stl" scale="0.001 0.001 0.001"/>
      </geometry>
      <material name="blue"/>
    </visual>
    <collision>
      <origin rpy="0.0 0.0 0.0" xyz="0.0 0.0 0.0"/>
      <geometry>
        <mesh filename="package://inail2arm_urdf/meshes/simple/mesh_shoulder-pitch.stl" scale="0.001 0.001 0.001"/>
      </geometry>
    </collision>
  </link>
  <!-- shoulder pitch-->
  <!-- elbow-yaw-->
  <link name="arm1_3">
    <inertial>
      <origin xyz="-1.2974906e-05 0.064319293 -0.03429615"/>
      <mass value="0.52461209"/>
      <inertia ixx="0.0015799731999999998" ixy="3.0297811e-07" ixz="4.1461879e-07" iyy="0.0010025017999999999" iyz="0.00038387214" izz="0.0014999643"/>
    </inertial>
    <visual>
      <origin rpy="0.0 0.0 0.0" xyz="0.0 0.0 0.0"/>
      <geometry>
        <mesh filename="package://inail2arm_urdf/meshes/mesh_elbow.stl" scale="0.001 0.001 0.001"/>
      </geometry>
      <material name="blue"/>
    </visual>
    <collision>
      <origin rpy="0.0 0.0 0.0" xyz="0.0 0.0 0.0"/>
      <geometry>
        <mesh filename="package://inail2arm_urdf/meshes/simple/mesh_elbow.stl" scale="0.001 0.001 0.001"/>
      </geometry>
    </collision>
  </link>
  <!-- elbow-yaw-->
  <!-- forearm-yaw -->
  <link name="arm1_4">
    <inertial>
      <origin xyz="-6.452875299999999e-05 -0.046448856999999996 0.13357443000000002"/>
      <mass value="2.0046544"/>
      <inertia ixx="0.023326476999999998" ixy="-1.7237335e-05" ixz="-2.9785178999999997e-05" iyy="0.02013323" iyz="0.006970601399999999" izz="0.0052212805"/>
    </inertial>
    <visual>
      <origin rpy="0.0 0.0 0.0" xyz="0.0 0.0 0.0"/>
      <geometry>
        <mesh filename="package://inail2arm_urdf/meshes/mesh_forearm-yaw.stl" scale="0.001 0.001 0.001"/>
      </geometry>
      <material name="blue"/>
    </visual>
    <collision>
      <origin rpy="0.0 0.0 0.0" xyz="0.0 0.0 0.0"/>
      <geometry>
        <mesh filename="package://inail2arm_urdf/meshes/simple/mesh_forearm-yaw.stl" scale="0.001 0.001 0.001"/>
      </geometry>
    </collision>
  </link>
  <!-- forearm-yaw -->
  <!--wrist-pitch -->
  <link name="arm1_5">
    <inertial>
      <origin xyz="-4.7450211e-05 0.017403047999999997 0.040478983999999996"/>
      <mass value="1.0418416"/>
      <inertia ixx="0.0018450264" ixy="-6.3813838e-07" ixz="1.6212593e-05" iyy="0.0011114155" iyz="-3.7623514e-05" izz="0.0018417393"/>
    </inertial>
    <visual>
      <origin rpy="0.0 0.0 0.0" xyz="0.0 0.0 0.0"/>
      <geometry>
        <mesh filename="package://inail2arm_urdf/meshes/mesh_wrist-pitch.stl" scale="0.001                0.001 0.001"/>
      </geometry>
      <material name="blue"/>
    </visual>
    <collision>
      <origin rpy="0.0 0.0 0.0" xyz="0.0 0.0 0.0"/>
      <geometry>
        <mesh filename="package://inail2arm_urdf/meshes/simple/mesh_wrist-pitch.stl" scale="0.001                0.001 0.001"/>
      </geometry>
    </collision>
  </link>
  <link name="arm1_6">
    <inertial>
      <origin xyz="-0.00099908245 0.0010236000000000002 0.017236136"/>
      <mass value="0.20700511"/>
      <inertia ixx="0.00015215801" ixy="5.6840238e-06" ixz="-1.6110538999999998e-06" iyy="0.00015336095" iyz="1.4745761999999999e-06" izz="0.00026680853"/>
    </inertial>
    <visual>
      <origin rpy="0.0 0.0 0.0" xyz="0.0 0.0 0.0"/>
      <geometry>
        <mesh filename="package://inail2arm_urdf/meshes/mesh_wrist-roll.stl" scale="0.001 0.001 0.001"/>
      </geometry>
      <material name="blue"/>
    </visual>
    <collision>
      <origin rpy="0.0 0.0 0.0" xyz="0.0 0.0 0.0"/>
      <geometry>
        <mesh filename="package://inail2arm_urdf/meshes/mesh_wrist-roll.stl" scale="0.001 0.001 0.001"/>
      </geometry>
    </collision>
  </link>
  <!--wrist-pitch -->
  <!-- /LINKS -->
  <!-- JOINTS -->
  <!-- shoulder yaw -->
  <joint name="j_arm1_1" type="revolute">
    <parent link="mount_frame_1"/>
    <child link="arm1_1"/>
    <axis xyz="0 0 1"/>
    <origin rpy="0 0 -0.7853981633975" xyz="0 0 0"/>
    <limit effort="147.0" lower="-2.85" upper="2.85" velocity="3.86"/>
  </joint>
  <!-- shoulder yaw -->
  <!-- shoulder pitch -->
  <joint name="j_arm1_2" type="revolute">
    <parent link="arm1_1"/>
    <child link="arm1_2"/>
    <origin rpy="1.570796326795 0.0 0.0" xyz="0.0 -0.051 0.079"/>
    <axis xyz="0 0 -1"/>
    <limit effort="147.0" lower="-2.0" upper="2.0" velocity="3.86"/>
  </joint>
  <!-- shoulder pitch -->
  <!-- elbow yaw -->
  <joint name="j_arm1_3" type="revolute">
    <parent link="arm1_2"/>
    <child link="arm1_3"/>
    <origin rpy="0.0 0.0 0.0" xyz="0.0 0.365095 0.0"/>
    <axis xyz="0 0 1"/>
    <limit effort="147.0" lower="-2.2" upper="2.2" velocity="6.06"/>
    <!-- Virtual limits for elbow joints, so elbow doesnt flip in undesired orientation: better use cartesio config file to set these-->
    <!-- <xacro:if value="${parent == 'mount_frame_1'}">
            <limit lower="${j_arm_3_lower[0]}" upper="${-10*toRad}" effort="${j_arm_3_torque[0]}" velocity="${j_arm_3_velocity[0]}" />
        </xacro:if>

        <xacro:if value="${parent == 'mount_frame_2'}">
            <limit lower="${10*toRad}" upper="${j_arm_3_upper[0]}" effort="${j_arm_3_torque[0]}" velocity="${j_arm_3_velocity[0]}" />
       </xacro:if> -->
  </joint>
  <!-- elbow yaw -->
  <!-- forearm yaw -->
  <joint name="j_arm1_4" type="revolute">
    <parent link="arm1_3"/>
    <child link="arm1_4"/>
    <origin rpy="-1.570796326795 0.0 0.0" xyz="0.0 0.0825 -0.051"/>
    <axis xyz="0 0 1"/>
    <limit effort="147.0" lower="-2.7" upper="2.7" velocity="6.06"/>
  </joint>
  <!-- forearm yaw -->
  <!-- wrist pitch-->
  <joint name="j_arm1_5" type="revolute">
    <parent link="arm1_4"/>
    <child link="arm1_5"/>
    <origin rpy="-1.570796326795 0.0 0.0" xyz="0.0 -0.043 0.2525"/>
    <axis xyz="0 0 1"/>
    <limit effort="55.0" lower="-2.2" upper="2.2" velocity="11.72"/>
  </joint>
  <!-- wrist pitch-->
  <!-- wrist2 pitch-->
  <joint name="j_arm1_6" type="revolute">
    <parent link="arm1_5"/>
    <child link="arm1_6"/>
    <origin rpy="1.570796326795 0.0 0.0" xyz="0.0 -0.033 0.043"/>
    <axis xyz="0 0 1"/>
    <limit effort="55.0" lower="-2.7" upper="2.7" velocity="11.72"/>
  </joint>
  <!-- /wrist2 pitch-->
  <link name="mount_frame_2">
    <inertial>
      <origin rpy="0.0 0.0 0.0" xyz="0.0 0.0 0.0"/>
      <mass value="0.00001"/>
      <inertia ixx="0.0" ixy="0.0" ixz="0.0" iyy="0.0" iyz="0.0" izz="0.0"/>
    </inertial>
  </link>
  <joint name="mount_joint_2" type="fixed">
    <parent link="base_link"/>
    <child link="mount_frame_2"/>
    <origin rpy="-0.7853981633975 0 0" xyz="0.065 0.153361940777 0.221661940777"/>
  </joint>
  <!-- LINKS -->
  <!-- shoulder yaw-->
  <link name="arm2_1">
    <inertial>
      <origin xyz="8.4798664e-05 -0.020782662 0.032183554999999996"/>
      <mass value="0.41054046"/>
      <inertia ixx="0.0012949444" ixy="-1.8773371e-06" ixz="1.2479427999999998e-06" iyy="0.0012303834999999998" iyz="0.00032390228999999997" izz="0.0008036788199999999"/>
    </inertial>
    <visual>
      <origin rpy="0.0 0.0 0.0" xyz="0.0 0.0 0.0"/>
      <geometry>
        <mesh filename="package://inail2arm_urdf/meshes/mesh_shoulder-yaw.stl" scale="0.001 0.001 0.001"/>
      </geometry>
      <material name="blue"/>
    </visual>
    <collision>
      <origin rpy="0.0 0.0 0.0" xyz="0.0 0.0 0.0"/>
      <geometry>
        <mesh filename="package://inail2arm_urdf/meshes/simple/mesh_shoulder-yaw.stl" scale="0.001 0.001 0.001"/>
      </geometry>
    </collision>
  </link>
  <!-- shoulder yaw-->
  <!-- shoulder pitch-->
  <link name="arm2_2">
    <inertial>
      <origin xyz="-3.636067e-05 0.16072685 -0.062849027"/>
      <mass value="3.2487988"/>
      <inertia ixx="0.090371217" ixy="9.791527499999999e-05" ixz="-5.558155099999999e-06" iyy="0.0065574254" iyz="-0.0029068254" izz="0.088276594"/>
    </inertial>
    <visual>
      <origin rpy="0.0 0.0 0.0" xyz="0.0 0.0 0.0"/>
      <geometry>
        <mesh filename="package://inail2arm_urdf/meshes/mesh_shoulder-pitch.stl" scale="0.001 0.001 0.001"/>
      </geometry>
      <material name="blue"/>
    </visual>
    <collision>
      <origin rpy="0.0 0.0 0.0" xyz="0.0 0.0 0.0"/>
      <geometry>
        <mesh filename="package://inail2arm_urdf/meshes/simple/mesh_shoulder-pitch.stl" scale="0.001 0.001 0.001"/>
      </geometry>
    </collision>
  </link>
  <!-- shoulder pitch-->
  <!-- elbow-yaw-->
  <link name="arm2_3">
    <inertial>
      <origin xyz="-1.2974906e-05 0.064319293 -0.03429615"/>
      <mass value="0.52461209"/>
      <inertia ixx="0.0015799731999999998" ixy="3.0297811e-07" ixz="4.1461879e-07" iyy="0.0010025017999999999" iyz="0.00038387214" izz="0.0014999643"/>
    </inertial>
    <visual>
      <origin rpy="0.0 0.0 0.0" xyz="0.0 0.0 0.0"/>
      <geometry>
        <mesh filename="package://inail2arm_urdf/meshes/mesh_elbow.stl" scale="0.001 0.001 0.001"/>
      </geometry>
      <material name="blue"/>
    </visual>
    <collision>
      <origin rpy="0.0 0.0 0.0" xyz="0.0 0.0 0.0"/>
      <geometry>
        <mesh filename="package://inail2arm_urdf/meshes/simple/mesh_elbow.stl" scale="0.001 0.001 0.001"/>
      </geometry>
    </collision>
  </link>
  <!-- elbow-yaw-->
  <!-- forearm-yaw -->
  <link name="arm2_4">
    <inertial>
      <origin xyz="-6.452875299999999e-05 -0.046448856999999996 0.13357443000000002"/>
      <mass value="2.0046544"/>
      <inertia ixx="0.023326476999999998" ixy="-1.7237335e-05" ixz="-2.9785178999999997e-05" iyy="0.02013323" iyz="0.006970601399999999" izz="0.0052212805"/>
    </inertial>
    <visual>
      <origin rpy="0.0 0.0 0.0" xyz="0.0 0.0 0.0"/>
      <geometry>
        <mesh filename="package://inail2arm_urdf/meshes/mesh_forearm-yaw.stl" scale="0.001 0.001 0.001"/>
      </geometry>
      <material name="blue"/>
    </visual>
    <collision>
      <origin rpy="0.0 0.0 0.0" xyz="0.0 0.0 0.0"/>
      <geometry>
        <mesh filename="package://inail2arm_urdf/meshes/simple/mesh_forearm-yaw.stl" scale="0.001 0.001 0.001"/>
      </geometry>
    </collision>
  </link>
  <!-- forearm-yaw -->
  <!--wrist-pitch -->
  <link name="arm2_5">
    <inertial>
      <origin xyz="-4.7450211e-05 0.017403047999999997 0.040478983999999996"/>
      <mass value="1.0418416"/>
      <inertia ixx="0.0018450264" ixy="-6.3813838e-07" ixz="1.6212593e-05" iyy="0.0011114155" iyz="-3.7623514e-05" izz="0.0018417393"/>
    </inertial>
    <visual>
      <origin rpy="0.0 0.0 0.0" xyz="0.0 0.0 0.0"/>
      <geometry>
        <mesh filename="package://inail2arm_urdf/meshes/mesh_wrist-pitch.stl" scale="0.001                0.001 0.001"/>
      </geometry>
      <material name="blue"/>
    </visual>
    <collision>
      <origin rpy="0.0 0.0 0.0" xyz="0.0 0.0 0.0"/>
      <geometry>
        <mesh filename="package://inail2arm_urdf/meshes/simple/mesh_wrist-pitch.stl" scale="0.001                0.001 0.001"/>
      </geometry>
    </collision>
  </link>
  <link name="arm2_6">
    <inertial>
      <origin xyz="-0.00099908245 0.0010236000000000002 0.017236136"/>
      <mass value="0.20700511"/>
      <inertia ixx="0.00015215801" ixy="5.6840238e-06" ixz="-1.6110538999999998e-06" iyy="0.00015336095" iyz="1.4745761999999999e-06" izz="0.00026680853"/>
    </inertial>
    <visual>
      <origin rpy="0.0 0.0 0.0" xyz="0.0 0.0 0.0"/>
      <geometry>
        <mesh filename="package://inail2arm_urdf/meshes/mesh_wrist-roll.stl" scale="0.001 0.001 0.001"/>
      </geometry>
      <material name="blue"/>
    </visual>
    <collision>
      <origin rpy="0.0 0.0 0.0" xyz="0.0 0.0 0.0"/>
      <geometry>
        <mesh filename="package://inail2arm_urdf/meshes/mesh_wrist-roll.stl" scale="0.001 0.001 0.001"/>
      </geometry>
    </collision>
  </link>
  <!--wrist-pitch -->
  <!-- /LINKS -->
  <!-- JOINTS -->
  <!-- shoulder yaw -->
  <joint name="j_arm2_1" type="revolute">
    <parent link="mount_frame_2"/>
    <child link="arm2_1"/>
    <axis xyz="0 0 1"/>
    <origin rpy="0 0 -2.3561944901925" xyz="0 0 0"/>
    <limit effort="147.0" lower="-2.85" upper="2.85" velocity="3.86"/>
  </joint>
  <!-- shoulder yaw -->
  <!-- shoulder pitch -->
  <joint name="j_arm2_2" type="revolute">
    <parent link="arm2_1"/>
    <child link="arm2_2"/>
    <origin rpy="1.570796326795 0.0 0.0" xyz="0.0 -0.051 0.079"/>
    <axis xyz="0 0 -1"/>
    <limit effort="147.0" lower="-2.0" upper="2.0" velocity="3.86"/>
  </joint>
  <!-- shoulder pitch -->
  <!-- elbow yaw -->
  <joint name="j_arm2_3" type="revolute">
    <parent link="arm2_2"/>
    <child link="arm2_3"/>
    <origin rpy="0.0 0.0 0.0" xyz="0.0 0.365095 0.0"/>
    <axis xyz="0 0 1"/>
    <limit effort="147.0" lower="-2.2" upper="2.2" velocity="6.06"/>
    <!-- Virtual limits for elbow joints, so elbow doesnt flip in undesired orientation: better use cartesio config file to set these-->
    <!-- <xacro:if value="${parent == 'mount_frame_1'}">
            <limit lower="${j_arm_3_lower[0]}" upper="${-10*toRad}" effort="${j_arm_3_torque[0]}" velocity="${j_arm_3_velocity[0]}" />
        </xacro:if>

        <xacro:if value="${parent == 'mount_frame_2'}">
            <limit lower="${10*toRad}" upper="${j_arm_3_upper[0]}" effort="${j_arm_3_torque[0]}" velocity="${j_arm_3_velocity[0]}" />
       </xacro:if> -->
  </joint>
  <!-- elbow yaw -->
  <!-- forearm yaw -->
  <joint name="j_arm2_4" type="revolute">
    <parent link="arm2_3"/>
    <child link="arm2_4"/>
    <origin rpy="-1.570796326795 0.0 0.0" xyz="0.0 0.0825 -0.051"/>
    <axis xyz="0 0 1"/>
    <limit effort="147.0" lower="-2.7" upper="2.7" velocity="6.06"/>
  </joint>
  <!-- forearm yaw -->
  <!-- wrist pitch-->
  <joint name="j_arm2_5" type="revolute">
    <parent link="arm2_4"/>
    <child link="arm2_5"/>
    <origin rpy="-1.570796326795 0.0 0.0" xyz="0.0 -0.043 0.2525"/>
    <axis xyz="0 0 1"/>
    <limit effort="55.0" lower="-2.2" upper="2.2" velocity="11.72"/>
  </joint>
  <!-- wrist pitch-->
  <!-- wrist2 pitch-->
  <joint name="j_arm2_6" type="revolute">
    <parent link="arm2_5"/>
    <child link="arm2_6"/>
    <origin rpy="1.570796326795 0.0 0.0" xyz="0.0 -0.033 0.043"/>
    <axis xyz="0 0 1"/>
    <limit effort="55.0" lower="-2.7" upper="2.7" velocity="11.72"/>
  </joint>
  <!-- /wrist2 pitch-->
  <!-- dagana on arm 1 -->
  <!-- <xacro:inail2_arm_ee arm_num="1"  parent="arm1_6" /> -->
  <!-- dagana on arm 2 -->
  <!-- <xacro:inail2_arm_ee arm_num="2"  parent="arm2_6" /> -->
  <!--- END EFFECTOR  -->
  <!-- <xacro:inail2_arm_ee arm_num="1"  parent="arm1_6">
    </xacro:inail2_arm_ee>
   
    <xacro:if value="${PROXIMITY_SENSORS}">
        <xacro:include filename="$(find inail2arm_urdf)/urdf/inail2arm_proximity_sensors.urdf.xacro" />
    </xacro:if> -->
</robot>

